# Logfile created on 2021-01-17 01:39:12 +0000 by logger.rb/v1.4.2
{"severity":"ERROR","time":"2021-01-17T01:39:12.694Z","correlation_id":"b610e6ecf91970ce59c509e7b434396e","exception.class":"Gitlab::Git::PreReceiveError","exception.message":"Internal API unreachable","exception.backtrace":["lib/gitlab/gitaly_client/operation_service.rb:345:in `user_commit_files'","lib/gitlab/git/repository.rb:902:in `block in multi_action'","lib/gitlab/git/wraps_gitaly_errors.rb:7:in `wrapped_gitaly_errors'","lib/gitlab/git/repository.rb:901:in `multi_action'","app/models/repository.rb:854:in `block in multi_action'","app/models/repository.rb:837:in `with_cache_hooks'","app/models/repository.rb:854:in `multi_action'","app/models/repository.rb:818:in `create_file'","app/services/files/create_service.rb:16:in `create_transformed_commit'","app/services/files/create_service.rb:10:in `create_commit!'","app/services/commits/create_service.rb:30:in `execute'","app/services/projects/create_service.rb:157:in `create_readme'","app/services/projects/create_service.rb:113:in `after_create_actions'","app/services/projects/create_service.rb:63:in `block in execute'","lib/gitlab/application_context.rb:54:in `block in use'","lib/gitlab/application_context.rb:54:in `use'","lib/gitlab/application_context.rb:21:in `with_context'","app/services/projects/create_service.rb:62:in `execute'","app/services/concerns/measurable.rb:35:in `execute'","lib/gitlab/database_importers/self_monitoring/project/create_service.rb:59:in `create_project'","app/models/concerns/stepable.rb:14:in `call'","app/models/concerns/stepable.rb:14:in `block in execute_steps'","app/models/concerns/stepable.rb:13:in `each'","app/models/concerns/stepable.rb:13:in `inject'","app/models/concerns/stepable.rb:13:in `execute_steps'","lib/gitlab/database_importers/self_monitoring/project/create_service.rb:27:in `execute'","(eval):3:in `block (2 levels) in run_file'","lib/tasks/gitlab/db.rake:64:in `block (3 levels) in \u003ctop (required)\u003e'"]}
